Workbook

Sheet Instrucciones
A1: Template — Planificación desde EDT/WBS a Carta Gantt · Caso 3: Horizonte Conecta (Constructora Horizonte)
A3: OBJETIVO
A4: Transformar una EDT/WBS en actividades, estimarlas, aplicar restricciones de calendario y construir cronograma y Carta Gantt.
A5: FLUJO DE TRABAJO
A6: 1 | B6: EDT-WBS | C6: Defina entregables y paquetes de trabajo.
A7: 2 | B7: Actividades | C7: Descomponga cada paquete en actividades concretas.
A8: 3 | B8: Planificación | C8: Defina dependencias, esfuerzo, recursos, disponibilidad y duración.
A9: 4 | B9: Calendario | C9: Registre jornada, feriados, vacaciones, recursos compartidos y fechas comprometidas.
A10: 5 | B10: Cronograma | C10: Defina fechas de inicio y fin considerando restricciones.
A11: 6 | B11: Carta Gantt | C11: Visualice temporalmente el cronograma.
A12: REGLA CLAVE | B12: La EDT define QUÉ se entrega; las actividades definen el trabajo; el cronograma define CUÁNDO.
A14: PROYECTO | B14: Horizonte Conecta – Plataforma de gestión operacional de obras
A15: PLAZO | B15: Inicio 05-10-2026 · cierre planificado 12-07-2027 · plazo máximo 04-08-2027 (10 meses) · reserva de cronograma: 16 días hábiles
A16: MÉTODO | B16: Duración = Esfuerzo (hp) / (N° recursos × h/día), redondeada hacia arriba. Fechas del Cronograma calculadas con WORKDAY sobre el calendario laboral (lun–vie, 8 h) excluyendo los feriados de la hoja Calendario (nombre 'Feriados').
A17: RUTA CRÍTICA | B17: Holgura total y ruta crítica calculadas por método CPM (pasada hacia adelante y hacia atrás). En la Carta Gantt: rojo = actividad crítica, azul = no crítica, rombo naranjo = hito, columna roja = fecha límite.
A18: NIVEL DE ESFUERZO | B18: A03 (seguimiento y control) y A28 (apoyo a los sprints) son actividades de nivel de esfuerzo: su duración cubre el período de la actividad a la que acompañan.

Sheet Actividades
A1: 2. Descomposición de paquetes de trabajo en actividades — Horizonte Conecta
A3: ID EDT | B3: ID Actividad | C3: Actividad (verbo + objeto) | D3: Resultado verificable | E3: Responsable / Rol | F3: ¿Terminada cuando...? | G3: Observaciones
A4: 1.1.1 | B4: A01 | C4: Constituir equipo y comité directivo, y realizar kick-off | D4: Acta de kick-off y matriz RACI | E4: Jefe de Proyecto | F4: El patrocinador firma el acta de kick-off | G4: Inicio y planificación
A5: 1.1.1 | B5: H01 | C5: Hito: Kick-off realizado | D5: Kick-off realizado | E5: Hito (responsable: Jefe de Proyecto) | F5: Acta de kick-off firmada | G5: HITO · Inicio y planificación
A6: 1.1.1 | B6: A02 | C6: Elaborar y aprobar plan de dirección del proyecto | D6: Plan de dirección con líneas base | E6: Jefe de Proyecto | F6: El comité aprueba alcance, cronograma y costos | G6: Inicio y planificación
A7: 1.1.2 | B7: A03 | C7: Realizar seguimiento y control (comités quincenales, riesgos y cambios) | D7: Informes quincenales y actas de comité | E7: Jefe de Proyecto | F7: Se emitió el último informe antes del cierre | G7: Nivel de esfuerzo: 4 h/día del JP
A8: 1.1.3 | B8: A04 | C8: Elaborar informe final, lecciones aprendidas y acta de cierre | D8: Acta de cierre firmada | E8: Jefe de Proyecto | F8: El patrocinador firma el acta de cierre | G8: Cierre del proyecto
A9: 1.1.3 | B9: H10 | C9: Hito: Cierre formal del proyecto | D9: Cierre formal del proyecto | E9: Hito (responsable: Jefe de Proyecto) | F9: Acta de cierre firmada | G9: HITO · Cierre del proyecto
A10: 1.2.1 | B10: A05 | C10: Levantar procesos en las 3 obras piloto y en oficina central | D10: Mapas de procesos actuales | E10: Analista Funcional / de Negocio + Diseñador UX/UI | F10: Se entrevistó a los 3 equipos de obra y a las áreas centrales | G10: Sesiones cortas en obra (≤ 45 min)
A11: 1.2.1 | B11: A06 | C11: Documentar diagnóstico y línea base de indicadores | D11: Informe de diagnóstico | E11: Analista Funcional / de Negocio | F11: El Product Owner acepta el informe | G11: Diagnóstico de procesos actuales
A12: 1.2.2 | B12: A07 | C12: Especificar requisitos e historias de usuario (incluye offline y seguridad) | D12: Catálogo de historias de usuario | E12: Analista Funcional / de Negocio | F12: Cada historia tiene criterio de aceptación | G12: Requisitos, indicadores y backlog
A13: 1.2.2 | B13: A08 | C13: Definir indicadores de las 6 preguntas de la gerencia y validarlos con Finanzas | D13: Fichas de indicadores validadas | E13: Analista de Datos / BI | F13: Finanzas aprueba fuente y fórmula de cada indicador | G13: Requisitos, indicadores y backlog
A14: 1.2.2 | B14: A09 | C14: Priorizar backlog en Release 1 y 2 y aprobar el alcance en comité | D14: Backlog priorizado y acta de alcance | E14: Analista Funcional / de Negocio + Jefe de Proyecto | F14: El comité aprueba el alcance y decide sobre Prevención de Riesgos | G14: Requisitos, indicadores y backlog
... A55: 1.10.1 | B55: A42 | C55: Elaborar documentación y manuales, y traspasar la operación a TI | D55: Acta de traspaso | E55: Arquitecto de Solución + Ingeniero DevOps / Cloud + Especialista Gestión del Cambio y Capacitación | F55: TI firma el acta de traspaso | G55: Documentación y traspaso a TI

Sheet Planificación
A1: 3. Planificación temporal — dependencias, esfuerzo, recursos y duración — Horizonte Conecta
A3: ID | B3: Actividad | C3: Predecesora(s) | D3: Tipo | E3: Esfuerzo (hp) | F3: N° recursos | G3: Disponibilidad (h/día) | H3: Duración calculada (días) | I3: Duración planificada (días) | J3: Recurso / Rol | K3: Observaciones
A4: A01 | B4: Constituir equipo y comité directivo, y realizar kick-off | C4: — | E4: 32 | F4: 1 | G4: 8 | H4: =IFERROR(E4/(F4*G4),"") -> 4 | I4: 4 | J4: Jefe de Proyecto
A5: H01 | B5: Hito: Kick-off realizado | C5: A01 | D5: FS | E5: 0 | F5: 0 | G5: 0 | H5: =IFERROR(E5/(F5*G5),"") | I5: 0 | J5: Hito
A6: A02 | B6: Elaborar y aprobar plan de dirección del proyecto | C6: H01 | D6: FS | E6: 80 | F6: 1 | G6: 8 | H6: =IFERROR(E6/(F6*G6),"") -> 10 | I6: 10 | J6: Jefe de Proyecto
A7: A03 | B7: Realizar seguimiento y control (comités quincenales, riesgos y cambios) | C7: A02 | D7: FS | E7: 664 | F7: 1 | G7: 4 | H7: =IFERROR(E7/(F7*G7),"") -> 166 | I7: 166 | J7: Jefe de Proyecto | K7: Nivel de esfuerzo: 4 h/día del JP; Termina con A40
A8: A04 | B8: Elaborar informe final, lecciones aprendidas y acta de cierre | C8: H09, A42 | D8: FS | E8: 32 | F8: 1 | G8: 8 | H8: =IFERROR(E8/(F8*G8),"") -> 4 | I8: 4 | J8: Jefe de Proyecto
A9: H10 | B9: Hito: Cierre formal del proyecto | C9: A04 | D9: FS | E9: 0 | F9: 0 | G9: 0 | H9: =IFERROR(E9/(F9*G9),"") | I9: 0 | J9: Hito
A10: A05 | B10: Levantar procesos en las 3 obras piloto y en oficina central | C10: H01 | D10: FS | E10: 96 | F10: 2 | G10: 8 | H10: =IFERROR(E10/(F10*G10),"") -> 6 | I10: 6 | J10: Analista Funcional / de Negocio + Diseñador UX/UI | K10: Sesiones cortas en obra (≤ 45 min)
A11: A06 | B11: Documentar diagnóstico y línea base de indicadores | C11: A05 | D11: FS | E11: 32 | F11: 1 | G11: 8 | H11: =IFERROR(E11/(F11*G11),"") -> 4 | I11: 4 | J11: Analista Funcional / de Negocio
A12: A07 | B12: Especificar requisitos e historias de usuario (incluye offline y seguridad) | C12: A06 | D12: FS | E12: 88 | F12: 1 | G12: 8 | H12: =IFERROR(E12/(F12*G12),"") -> 11 | I12: 11 | J12: Analista Funcional / de Negocio
A13: A08 | B13: Definir indicadores de las 6 preguntas de la gerencia y validarlos con Finanzas | C13: A06 | D13: FS | E13: 56 | F13: 1 | G13: 8 | H13: =IFERROR(E13/(F13*G13),"") -> 7 | I13: 7 | J13: Analista de Datos / BI
A14: A09 | B14: Priorizar backlog en Release 1 y 2 y aprobar el alcance en comité | C14: A07, A08 | D14: FS | E14: 16 | F14: 2 | G14: 4 | H14: =IFERROR(E14/(F14*G14),"") -> 2 | I14: 2 | J14: Analista Funcional / de Negocio + Jefe de Proyecto
A15: H02 | B15: Hito: Alcance aprobado | C15: A09 | D15: FS | E15: 0 | F15: 0 | G15: 0 | H15: =IFERROR(E15/(F15*G15),"") | I15: 0 | J15: Hito
A16: A10 | B16: Probar la API del sistema de compras con el proveedor (prueba de concepto) | C16: H01 | D16: FS | E16: 80 | F16: 1 | G16: 8 | H16: =IFERROR(E16/(F16*G16),"") -> 10 | I16: 10 | J16: Desarrollador de Integraciones | K16: Se adelanta porque es el mayor riesgo técnico
A17: A11 | B17: Diseñar arquitectura, integraciones y modelo de datos, y aprobarlos con TI | C17: A06, A10 | D17: FS | E17: 152 | F17: 1 | G17: 8 | H17: =IFERROR(E17/(F17*G17),"") -> 19 | I17: 19 | J17: Arquitecto de Solución
A18: A12 | B18: Diseñar el prototipo UX/UI y validarlo con jefes de obra | C18: H02 | D18: FS | E18: 152 | F18: 1 | G18: 8 | H18: =IFERROR(E18/(F18*G18),"") -> 19 | I18: 19 | J18: Diseñador UX/UI
A19: H03 | B19: Hito: Diseño de solución aprobado | C19: A11, A12 | D19: FS | E19: 0 | F19: 0 | G19: 0 | H19: =IFERROR(E19/(F19*G19),"") | I19: 0 | J19: Hito
A20: A13 | B20: Provisionar ambientes cloud, CI/CD, monitoreo y respaldos | C20: A11 | D20: FS | E20: 90 | F20: 1 | G20: 6 | H20: =IFERROR(E20/(F20*G20),"") -> 15 | I20: 15 | J20: Ingeniero DevOps / Cloud
A21: A14 | B21: Desarrollar núcleo: usuarios, roles por obra, auditoría y maestros | C21: H03, A13 | D21: FS | E21: 224 | F21: 2 | G21: 8 | H21: =IFERROR(E21/(F21*G21),"") -> 14 | I21: 14 | J21: Desarrollador Backend
A22: A15 | B22: Desarrollar la app móvil offline y probarla en terreno | C22: H03 | D22: FS | E22: 288 | F22: 2 | G22: 8 | H22: =IFERROR(E22/(F22*G22),"") -> 18 | I22: 18 | J22: Desarrollador Frontend/Móvil
A23: H04 | B23: Hito: Plataforma base operativa | C23: A14, A15, A16 | D23: FS | E23: 0 | F23: 0 | G23: 0 | H23: =IFERROR(E23/(F23*G23),"") | I23: 0 | J23: Hito
A24: A16 | B24: Integrar el inicio de sesión corporativo (SSO) y el repositorio documental Microsoft | C24: A13, A10 | D24: FS | E24: 144 | F24: 1 | G24: 8 | H24: =IFERROR(E24/(F24*G24),"") -> 18 | I24: 18 | J24: Desarrollador de Integraciones
A25: A17 | B25: Integrar el sistema de compras (API) y validarlo con Adquisiciones | C25: A16 | D25: FS | E25: 176 | F25: 1 | G25: 8 | H25: =IFERROR(E25/(F25*G25),"") -> 22 | I25: 22 | J25: Desarrollador de Integraciones
A26: A18 | B26: Integrar el ERP en modo lectura y conciliar montos con Finanzas | C26: A17 | D26: FS | E26: 136 | F26: 1 | G26: 8 | H26: =IFERROR(E26/(F26*G26),"") -> 17 | I26: 17 | J26: Desarrollador de Integraciones
A27: A19 | B27: Desarrollar importación de programación, cálculo de avance y alertas de bloqueo | C27: H04 | D27: FS | E27: 216 | F27: 1 | G27: 8 | H27: =IFERROR(E27/(F27*G27),"") -> 27 | I27: 27 | J27: Desarrollador Backend | K27: Célula A (backend)
A28: A20 | B28: Desarrollar el registro móvil de avance por partida con fotos | C28: H04 | D28: FS | E28: 176 | F28: 1 | G28: 8 | H28: =IFERROR(E28/(F28*G28),"") -> 22 | I28: 22 | J28: Desarrollador Frontend/Móvil | K28: Célula A (móvil)
A29: A21 | B29: Desarrollar el módulo de observaciones con fotos y flujo de cierre | C29: H04 | D29: FS | E29: 224 | F29: 2 | G29: 8 | H29: =IFERROR(E29/(F29*G29),"") -> 14 | I29: 14 | J29: Desarrollador Backend + Desarrollador Frontend/Móvil | K29: Célula B
A30: A22 | B30: Desarrollar el catálogo y el visor offline de planos vigentes | C30: A21, A16 | D30: FS | E30: 176 | F30: 2 | G30: 8 | H30: =IFERROR(E30/(F30*G30),"") -> 11 | I30: 11 | J30: Desarrollador Backend + Desarrollador Frontend/Móvil | K30: Célula B
A31: A23 | B31: Desarrollar el módulo de materiales (OC, recepción móvil y conciliación con facturas) | C31: A29, A17 | D31: FS | E31: 256 | F31: 2 | G31: 8 | H31: =IFERROR(E31/(F31*G31),"") -> 16 | I31: 16 | J31: Desarrollador Backend + Desarrollador Frontend/Móvil | K31: Célula A, después de corregir defectos de R1
A32: A24 | B32: Desarrollar el módulo de subcontratos y estados de pago | C32: A22 | D32: FS | E32: 288 | F32: 2 | G32: 8 | H32: =IFERROR(E32/(F32*G32),"") -> 18 | I32: 18 | J32: Desarrollador Backend + Desarrollador Frontend/Móvil | K32: Célula B
A33: A25 | B33: Construir el modelo analítico con cargas diarias | C33: H04, A08 | D33: FS | E33: 136 | F33: 1 | G33: 8 | H33: =IFERROR(E33/(F33*G33),"") -> 17 | I33: 17 | J33: Analista de Datos / BI
A34: A26 | B34: Desarrollar el tablero ejecutivo y validarlo con Gerencia y Finanzas | C34: A25, A18 | D34: FS | E34: 128 | F34: 1 | G34: 8 | H34: =IFERROR(E34/(F34*G34),"") -> 16 | I34: 16 | J34: Analista de Datos / BI
A35: A27 | B35: Elaborar el plan y los casos de prueba | C35: H02 | D35: FS | E35: 96 | F35: 1 | G35: 8 | H35: =IFERROR(E35/(F35*G35),"") -> 12 | I35: 12 | J35: Analista QA
A36: A28 | B36: Apoyar los sprints: refinamiento, diseño de detalle, QA continuo, ambientes y revisión técnica | C36: H04 | D36: FS | E36: 860 | F36: 5 | G36: 4 | H36: =IFERROR(E36/(F36*G36),"") -> 43 | I36: 43 | J36: Analista Funcional / de Negocio + Diseñador UX/UI + Analista QA + Ingeniero DevOps / Cloud + Arquitecto de Solución | K36: Nivel de esfuerzo: 4 h/día de analista, UX, QA, DevOps y arquitecto; Termina con A24
A37: A29 | B37: Ejecutar pruebas de sistema de Release 1 y corregir defectos | C37: A19, A20, A22, A27 | D37: FS | E37: 240 | F37: 3 | G37: 8 | H37: =IFERROR(E37/(F37*G37),"") -> 10 | I37: 10 | J37: Analista QA + Desarrollador Backend + Desarrollador Frontend/Móvil | K37: 1 QA + célula A (1 backend y 1 móvil) corrigiendo defectos
A38: A30 | B38: Realizar la prueba de aceptación (UAT) de Release 1 con usuarios de obra | C38: A29 | D38: FS | E38: 40 | F38: 2 | G38: 4 | H38: =IFERROR(E38/(F38*G38),"") -> 5 | I38: 5 | J38: Analista QA + Analista Funcional / de Negocio | K38: 4 h/día por disponibilidad de usuarios de obra
A39: H05 | B39: Hito: Release 1 aceptada | C39: A30 | D39: FS | E39: 0 | F39: 0 | G39: 0 | H39: =IFERROR(E39/(F39*G39),"") | I39: 0 | J39: Hito
A40: A31 | B40: Ejecutar pruebas de sistema de Release 2 (con regresión) y corregir defectos | C40: A23, A24, A26, H05 | D40: FS | E40: 480 | F40: 6 | G40: 8 | H40: =IFERROR(E40/(F40*G40),"") -> 10 | I40: 10 | J40: Analista QA + Desarrollador Backend + Desarrollador Frontend/Móvil | K40: 2 QA + las 2 células de desarrollo
A41: A32 | B41: Ejecutar la prueba de seguridad externa y corregir hallazgos | C41: A31 | D41: FS | E41: 24 | F41: 1 | G41: 3 | H41: =IFERROR(E41/(F41*G41),"") -> 8 | I41: 8 | J41: Ingeniero DevOps / Cloud | K41: Servicio externo; duración fijada por el proveedor; Duración planificada ajustada (no sólo esfuerzo)
...

Sheet Calendario
A1: 4. Calendario del proyecto y restricciones — Horizonte Conecta
A3: Parámetro | B3: Valor | C3: Unidad / Tipo | D3: Observaciones
A4: Horas laborales por día | B4: 8 | C4: h/día | D4: Modificar según jornada real
A5: Días laborales por semana | B5: 5 | C5: días | D5: Normalmente lunes a viernes
A6: Fecha inicio del proyecto | B6: 46300 | C6: fecha | D6: Lunes 05-10-2026 (tras aprobación del charter el 02-10-2026)
A7: Fecha comprometida final | B7: 46603 | C7: fecha | D7: Plazo máximo de 10 meses definido por la constructora
A8: Calendario | B8: Laboral | C8: tipo | D8: Considere fines de semana y feriados
A9: Zona / contexto | B9: Chile – feriados nacionales | C9: texto | D9: Obras piloto: Viña del Mar (Valparaíso), Santiago (RM) y Rancagua (O'Higgins)
A11: Rango con nombre 'Feriados' = B13:B21 (usado por WORKDAY en Cronograma)
A12: Tipo | B12: Desde | C12: Hasta | D12: Persona/Recurso | E12: Descripción | F12: Afecta actividad | G12: Impacto | H12: Observaciones
A13: Feriado | B13: 46307 | C13: 46307 | D13: Todos | E13: Feriado nacional: Encuentro de Dos Mundos | F13: Todas las activas ese día | G13: Día no laborable (WORKDAY lo excluye) | H13: Fuente: feriados.cl
A14: Feriado | B14: 46364 | C14: 46364 | D14: Todos | E14: Feriado nacional: Inmaculada Concepción | F14: Todas las activas ese día | G14: Día no laborable (WORKDAY lo excluye) | H14: Fuente: feriados.cl
A15: Feriado | B15: 46381 | C15: 46381 | D15: Todos | E15: Feriado nacional: Navidad | F15: Todas las activas ese día | G15: Día no laborable (WORKDAY lo excluye) | H15: Fuente: feriados.cl
A16: Feriado | B16: 46388 | C16: 46388 | D16: Todos | E16: Feriado nacional: Año Nuevo | F16: Todas las activas ese día | G16: Día no laborable (WORKDAY lo excluye) | H16: Fuente: feriados.cl
A17: Feriado | B17: 46472 | C17: 46472 | D17: Todos | E17: Feriado nacional: Viernes Santo | F17: Todas las activas ese día | G17: Día no laborable (WORKDAY lo excluye) | H17: Fuente: feriados.cl
A18: Feriado | B18: 46528 | C18: 46528 | D18: Todos | E18: Feriado nacional: Día de las Glorias Navales | F18: Todas las activas ese día | G18: Día no laborable (WORKDAY lo excluye) | H18: Fuente: feriados.cl
A19: Feriado | B19: 46559 | C19: 46559 | D19: Todos | E19: Feriado nacional: Día Nacional de los Pueblos Indígenas | F19: Todas las activas ese día | G19: Día no laborable (WORKDAY lo excluye) | H19: Fuente: feriados.cl
A20: Feriado | B20: 46566 | C20: 46566 | D20: Todos | E20: Feriado nacional: San Pedro y San Pablo | F20: Todas las activas ese día | G20: Día no laborable (WORKDAY lo excluye) | H20: Fuente: feriados.cl
A21: Feriado | B21: 46584 | C21: 46584 | D21: Todos | E21: Feriado nacional: Día de la Virgen del Carmen | F21: Todas las activas ese día | G21: Día no laborable (WORKDAY lo excluye) | H21: Fuente: feriados.cl
A22: Fecha comprometida | B22: 46603 | C22: 46603 | D22: Proyecto | E22: Plazo máximo del proyecto (10 meses) | F22: H10 | G22: Cierre debe ser anterior | H22: Cierre planificado 12-07-2027: reserva de 3 semanas
A23: Recurso compartido | B23: 46300 | C23: 46560 | D23: Jefes de obra y oficina técnica | E23: Disponibilidad máx. 2 h/semana para el proyecto | F23: A05, A12, A30, A35 | G23: Sesiones ≤ 45 min en obra; UAT a 4 h/día | H23: SUP-06
A24: Recurso compartido | B24: 46300 | C24: 46518 | D24: TI corporativa | E24: Accesos a identidad, repositorio Microsoft y ERP | F24: A11, A13, A16, A18 | G24: Solicitudes en semana 1; mesa técnica semanal | H24: R-08
... A29: Otro | B29: 46300 | C29: 46560 | D29: Obras piloto | E29: Las faenas no se detienen: despliegues y capacitación fuera de horario crítico | F29: A36, A39, A35 | G29: Despliegues de tarde o fin de jornada | H29: RES-08

Sheet Cronograma
A1: 5. Cronograma base — Horizonte Conecta (fechas calculadas con WORKDAY y feriados)
A3: ID | B3: Actividad | C3: Predecesora(s) | D3: Tipo | E3: Duración (días) | F3: Recurso / Rol | G3: Fecha inicio | H3: Fecha fin | I3: Hito | J3: % Avance | K3: Observaciones | L3: Holgura total (días háb.) | M3: Ruta crítica | N3: Paquete EDT | O3: Entregable EDT (nivel 2)
A4: A01 | B4: Constituir equipo y comité directivo, y realizar kick-off | C4: — | E4: =Planificación!I4 -> 4 | F4: Jefe de Proyecto | G4: =WORKDAY(Calendario!$B$6-1,1,Feriados) -> 46300 | H4: =IF(E4=0,G4,WORKDAY(G4,E4-1,Feriados)) -> 46303 | I4: No | J4: 0% | L4: 0 | M4: Sí | N4: 1.1.1 | O4: 1.1
A5: H01 | B5: Hito: Kick-off realizado | C5: A01 | D5: FS | E5: =Planificación!I5 -> 0 | F5: Hito | G5: =MAX(H4) -> 46303 | H5: =IF(E5=0,G5,WORKDAY(G5,E5-1,Feriados)) -> 46303 | I5: Sí | J5: 0% | L5: 0 | M5: Sí | N5: 1.1.1 | O5: 1.1
A6: A02 | B6: Elaborar y aprobar plan de dirección del proyecto | C6: H01 | D6: FS | E6: =Planificación!I6 -> 10 | F6: Jefe de Proyecto | G6: =WORKDAY(H5,1,Feriados) -> 46304 | H6: =IF(E6=0,G6,WORKDAY(G6,E6-1,Feriados)) -> 46318 | I6: No | J6: 0% | L6: 13 | M6: No | N6: 1.1.1 | O6: 1.1
A7: A03 | B7: Realizar seguimiento y control (comités quincenales, riesgos y cambios) | C7: A02 | D7: FS | E7: =Planificación!I7 -> 166 | F7: Jefe de Proyecto | G7: =WORKDAY(H6,1,Feriados) -> 46321 | H7: =IF(E7=0,G7,WORKDAY(G7,E7-1,Feriados)) -> 46560 | I7: No | J7: 0% | K7: Nivel de esfuerzo: 4 h/día del JP | L7: — | M7: No | N7: 1.1.2 | O7: 1.1
A8: A04 | B8: Elaborar informe final, lecciones aprendidas y acta de cierre | C8: H09, A42 | D8: FS | E8: =Planificación!I8 -> 4 | F8: Jefe de Proyecto | G8: =WORKDAY(MAX(H54,H55),1,Feriados) -> 46575 | H8: =IF(E8=0,G8,WORKDAY(G8,E8-1,Feriados)) -> 46580 | I8: No | J8: 0% | L8: 0 | M8: Sí | N8: 1.1.3 | O8: 1.1
A9: H10 | B9: Hito: Cierre formal del proyecto | C9: A04 | D9: FS | E9: =Planificación!I9 -> 0 | F9: Hito | G9: =MAX(H8) -> 46580 | H9: =IF(E9=0,G9,WORKDAY(G9,E9-1,Feriados)) -> 46580 | I9: Sí | J9: 0% | L9: 0 | M9: Sí | N9: 1.1.3 | O9: 1.1
A10: A05 | B10: Levantar procesos en las 3 obras piloto y en oficina central | C10: H01 | D10: FS | E10: =Planificación!I10 -> 6 | F10: Analista Funcional / de Negocio + Diseñador UX/UI | G10: =WORKDAY(H5,1,Feriados) -> 46304 | H10: =IF(E10=0,G10,WORKDAY(G10,E10-1,Feriados)) -> 46314 | I10: No | J10: 0% | K10: Sesiones cortas en obra (≤ 45 min) | L10: 0 | M10: Sí | N10: 1.2.1 | O10: 1.2
A11: A06 | B11: Documentar diagnóstico y línea base de indicadores | C11: A05 | D11: FS | E11: =Planificación!I11 -> 4 | F11: Analista Funcional / de Negocio | G11: =WORKDAY(H10,1,Feriados) -> 46315 | H11: =IF(E11=0,G11,WORKDAY(G11,E11-1,Feriados)) -> 46318 | I11: No | J11: 0% | L11: 0 | M11: Sí | N11: 1.2.1 | O11: 1.2
A12: A07 | B12: Especificar requisitos e historias de usuario (incluye offline y seguridad) | C12: A06 | D12: FS | E12: =Planificación!I12 -> 11 | F12: Analista Funcional / de Negocio | G12: =WORKDAY(H11,1,Feriados) -> 46321 | H12: =IF(E12=0,G12,WORKDAY(G12,E12-1,Feriados)) -> 46335 | I12: No | J12: 0% | L12: 4 | M12: No | N12: 1.2.2 | O12: 1.2
A13: A08 | B13: Definir indicadores de las 6 preguntas de la gerencia y validarlos con Finanzas | C13: A06 | D13: FS | E13: =Planificación!I13 -> 7 | F13: Analista de Datos / BI | G13: =WORKDAY(H11,1,Feriados) -> 46321 | H13: =IF(E13=0,G13,WORKDAY(G13,E13-1,Feriados)) -> 46329 | I13: No | J13: 0% | L13: 8 | M13: No | N13: 1.2.2 | O13: 1.2
A14: A09 | B14: Priorizar backlog en Release 1 y 2 y aprobar el alcance en comité | C14: A07, A08 | D14: FS | E14: =Planificación!I14 -> 2 | F14: Analista Funcional / de Negocio + Jefe de Proyecto | G14: =WORKDAY(MAX(H12,H13),1,Feriados) -> 46336 | H14: =IF(E14=0,G14,WORKDAY(G14,E14-1,Feriados)) -> 46337 | I14: No | J14: 0% | L14: 4 | M14: No | N14: 1.2.2 | O14: 1.2
A15: H02 | B15: Hito: Alcance aprobado | C15: A09 | D15: FS | E15: =Planificación!I15 -> 0 | F15: Hito | G15: =MAX(H14) -> 46337 | H15: =IF(E15=0,G15,WORKDAY(G15,E15-1,Feriados)) -> 46337 | I15: Sí | J15: 0% | L15: 4 | M15: No | N15: 1.2.2 | O15: 1.2
A16: A10 | B16: Probar la API del sistema de compras con el proveedor (prueba de concepto) | C16: H01 | D16: FS | E16: =Planificación!I16 -> 10 | F16: Desarrollador de Integraciones | G16: =WORKDAY(H5,1,Feriados) -> 46304 | H16: =IF(E16=0,G16,WORKDAY(G16,E16-1,Feriados)) -> 46318 | I16: No | J16: 0% | K16: Se adelanta porque es el mayor riesgo técnico | L16: 0 | M16: Sí | N16: 1.3.1 | O16: 1.3
A17: A11 | B17: Diseñar arquitectura, integraciones y modelo de datos, y aprobarlos con TI | C17: A06, A10 | D17: FS | E17: =Planificación!I17 -> 19 | F17: Arquitecto de Solución | G17: =WORKDAY(MAX(H11,H16),1,Feriados) -> 46321 | H17: =IF(E17=0,G17,WORKDAY(G17,E17-1,Feriados)) -> 46345 | I17: No | J17: 0% | L17: 0 | M17: Sí | N17: 1.3.1 | O17: 1.3
A18: A12 | B18: Diseñar el prototipo UX/UI y validarlo con jefes de obra | C18: H02 | D18: FS | E18: =Planificación!I18 -> 19 | F18: Diseñador UX/UI | G18: =WORKDAY(H15,1,Feriados) -> 46338 | H18: =IF(E18=0,G18,WORKDAY(G18,E18-1,Feriados)) -> 46365 | I18: No | J18: 0% | L18: 4 | M18: No | N18: 1.3.2 | O18: 1.3
A19: H03 | B19: Hito: Diseño de solución aprobado | C19: A11, A12 | D19: FS | E19: =Planificación!I19 -> 0 | F19: Hito | G19: =MAX(H17,H18) -> 46365 | H19: =IF(E19=0,G19,WORKDAY(G19,E19-1,Feriados)) -> 46365 | I19: Sí | J19: 0% | L19: 4 | M19: No | N19: 1.3.2 | O19: 1.3
A20: A13 | B20: Provisionar ambientes cloud, CI/CD, monitoreo y respaldos | C20: A11 | D20: FS | E20: =Planificación!I20 -> 15 | F20: Ingeniero DevOps / Cloud | G20: =WORKDAY(H17,1,Feriados) -> 46346 | H20: =IF(E20=0,G20,WORKDAY(G20,E20-1,Feriados)) -> 46367 | I20: No | J20: 0% | L20: 0 | M20: Sí | N20: 1.4.1 | O20: 1.4
A21: A14 | B21: Desarrollar núcleo: usuarios, roles por obra, auditoría y maestros | C21: H03, A13 | D21: FS | E21: =Planificación!I21 -> 14 | F21: Desarrollador Backend | G21: =WORKDAY(MAX(H19,H20),1,Feriados) -> 46370 | H21: =IF(E21=0,G21,WORKDAY(G21,E21-1,Feriados)) -> 46391 | I21: No | J21: 0% | L21: 6 | M21: No | N21: 1.4.2 | O21: 1.4
A22: A15 | B22: Desarrollar la app móvil offline y probarla en terreno | C22: H03 | D22: FS | E22: =Planificación!I22 -> 18 | F22: Desarrollador Frontend/Móvil | G22: =WORKDAY(H19,1,Feriados) -> 46366 | H22: =IF(E22=0,G22,WORKDAY(G22,E22-1,Feriados)) -> 46393 | I22: No | J22: 0% | L22: 4 | M22: No | N22: 1.4.2 | O22: 1.4
A23: H04 | B23: Hito: Plataforma base operativa | C23: A14, A15, A16 | D23: FS | E23: =Planificación!I23 -> 0 | F23: Hito | G23: =MAX(H21,H22,H24) -> 46395 | H23: =IF(E23=0,G23,WORKDAY(G23,E23-1,Feriados)) -> 46395 | I23: Sí | J23: 0% | L23: 2 | M23: No | N23: 1.4.2 | O23: 1.4
A24: A16 | B24: Integrar el inicio de sesión corporativo (SSO) y el repositorio documental Microsoft | C24: A13, A10 | D24: FS | E24: =Planificación!I24 -> 18 | F24: Desarrollador de Integraciones | G24: =WORKDAY(MAX(H20,H16),1,Feriados) -> 46370 | H24: =IF(E24=0,G24,WORKDAY(G24,E24-1,Feriados)) -> 46395 | I24: No | J24: 0% | L24: 0 | M24: Sí | N24: 1.5.1 | O24: 1.5
A25: A17 | B25: Integrar el sistema de compras (API) y validarlo con Adquisiciones | C25: A16 | D25: FS | E25: =Planificación!I25 -> 22 | F25: Desarrollador de Integraciones | G25: =WORKDAY(H24,1,Feriados) -> 46398 | H25: =IF(E25=0,G25,WORKDAY(G25,E25-1,Feriados)) -> 46427 | I25: No | J25: 0% | L25: 0 | M25: Sí | N25: 1.5.2 | O25: 1.5
A26: A18 | B26: Integrar el ERP en modo lectura y conciliar montos con Finanzas | C26: A17 | D26: FS | E26: =Planificación!I26 -> 17 | F26: Desarrollador de Integraciones | G26: =WORKDAY(H25,1,Feriados) -> 46428 | H26: =IF(E26=0,G26,WORKDAY(G26,E26-1,Feriados)) -> 46450 | I26: No | J26: 0% | L26: 0 | M26: Sí | N26: 1.5.2 | O26: 1.5
A27: A19 | B27: Desarrollar importación de programación, cálculo de avance y alertas de bloqueo | C27: H04 | D27: FS | E27: =Planificación!I27 -> 27 | F27: Desarrollador Backend | G27: =WORKDAY(H23,1,Feriados) -> 46398 | H27: =IF(E27=0,G27,WORKDAY(G27,E27-1,Feriados)) -> 46434 | I27: No | J27: 0% | K27: Célula A (backend) | L27: 2 | M27: No | N27: 1.6.1 | O27: 1.6
A28: A20 | B28: Desarrollar el registro móvil de avance por partida con fotos | C28: H04 | D28: FS | E28: =Planificación!I28 -> 22 | F28: Desarrollador Frontend/Móvil | G28: =WORKDAY(H23,1,Feriados) -> 46398 | H28: =IF(E28=0,G28,WORKDAY(G28,E28-1,Feriados)) -> 46427 | I28: No | J28: 0% | K28: Célula A (móvil) | L28: 7 | M28: No | N28: 1.6.1 | O28: 1.6
A29: A21 | B29: Desarrollar el módulo de observaciones con fotos y flujo de cierre | C29: H04 | D29: FS | E29: =Planificación!I29 -> 14 | F29: Desarrollador Backend + Desarrollador Frontend/Móvil | G29: =WORKDAY(H23,1,Feriados) -> 46398 | H29: =IF(E29=0,G29,WORKDAY(G29,E29-1,Feriados)) -> 46415 | I29: No | J29: 0% | K29: Célula B | L29: 4 | M29: No | N29: 1.6.2 | O29: 1.6
A30: A22 | B30: Desarrollar el catálogo y el visor offline de planos vigentes | C30: A21, A16 | D30: FS | E30: =Planificación!I30 -> 11 | F30: Desarrollador Backend + Desarrollador Frontend/Móvil | G30: =WORKDAY(MAX(H29,H24),1,Feriados) -> 46416 | H30: =IF(E30=0,G30,WORKDAY(G30,E30-1,Feriados)) -> 46430 | I30: No | J30: 0% | K30: Célula B | L30: 4 | M30: No | N30: 1.6.3 | O30: 1.6
A31: A23 | B31: Desarrollar el módulo de materiales (OC, recepción móvil y conciliación con facturas) | C31: A29, A17 | D31: FS | E31: =Planificación!I31 -> 16 | F31: Desarrollador Backend + Desarrollador Frontend/Móvil | G31: =WORKDAY(MAX(H37,H25),1,Feriados) -> 46449 | H31: =IF(E31=0,G31,WORKDAY(G31,E31-1,Feriados)) -> 46470 | I31: No | J31: 0% | K31: Célula A, después de corregir defectos de R1 | L31: 2 | M31: No | N31: 1.7.1 | O31: 1.7
A32: A24 | B32: Desarrollar el módulo de subcontratos y estados de pago | C32: A22 | D32: FS | E32: =Planificación!I32 -> 18 | F32: Desarrollador Backend + Desarrollador Frontend/Móvil | G32: =WORKDAY(H30,1,Feriados) -> 46433 | H32: =IF(E32=0,G32,WORKDAY(G32,E32-1,Feriados)) -> 46456 | I32: No | J32: 0% | K32: Célula B | L32: 12 | M32: No | N32: 1.7.2 | O32: 1.7
A33: A25 | B33: Construir el modelo analítico con cargas diarias | C33: H04, A08 | D33: FS | E33: =Planificación!I33 -> 17 | F33: Analista de Datos / BI | G33: =WORKDAY(MAX(H23,H13),1,Feriados) -> 46398 | H33: =IF(E33=0,G33,WORKDAY(G33,E33-1,Feriados)) -> 46420 | I33: No | J33: 0% | L33: 22 | M33: No | N33: 1.7.3 | O33: 1.7
A34: A26 | B34: Desarrollar el tablero ejecutivo y validarlo con Gerencia y Finanzas | C34: A25, A18 | D34: FS | E34: =Planificación!I34 -> 16 | F34: Analista de Datos / BI | G34: =WORKDAY(MAX(H33,H26),1,Feriados) -> 46451 | H34: =IF(E34=0,G34,WORKDAY(G34,E34-1,Feriados)) -> 46475 | I34: No | J34: 0% | L34: 0 | M34: Sí | N34: 1.7.3 | O34: 1.7
A35: A27 | B35: Elaborar el plan y los casos de prueba | C35: H02 | D35: FS | E35: =Planificación!I35 -> 12 | F35: Analista QA | G35: =WORKDAY(H15,1,Feriados) -> 46338 | H35: =IF(E35=0,G35,WORKDAY(G35,E35-1,Feriados)) -> 46353 | I35: No | J35: 0% | L35: 56 | M35: No | N35: 1.8.1 | O35: 1.8
A36: A28 | B36: Apoyar los sprints: refinamiento, diseño de detalle, QA continuo, ambientes y revisión técnica | C36: H04 | D36: FS | E36: =Planificación!I36 -> 43 | F36: Analista Funcional / de Negocio + Diseñador UX/UI + Analista QA + Ingeniero DevOps / Cloud + Arquitecto de Solución | G36: =WORKDAY(H23,1,Feriados) -> 46398 | H36: =IF(E36=0,G36,WORKDAY(G36,E36-1,Feriados)) -> 46456 | I36: No | J36: 0% | K36: Nivel de esfuerzo: 4 h/día de analista, UX, QA, DevOps y arquitecto | L36: — | M36: No | N36: 1.8.1 | O36: 1.8
A37: A29 | B37: Ejecutar pruebas de sistema de Release 1 y corregir defectos | C37: A19, A20, A22, A27 | D37: FS | E37: =Planificación!I37 -> 10 | F37: Analista QA + Desarrollador Backend + Desarrollador Frontend/Móvil | G37: =WORKDAY(MAX(H27,H28,H30,H35),1,Feriados) -> 46435 | H37: =IF(E37=0,G37,WORKDAY(G37,E37-1,Feriados)) -> 46448 | I37: No | J37: 0% | K37: 1 QA + célula A (1 backend y 1 móvil) corrigiendo defectos | L37: 2 | M37: No | N37: 1.8.2 | O37: 1.8
A38: A30 | B38: Realizar la prueba de aceptación (UAT) de Release 1 con usuarios de obra | C38: A29 | D38: FS | E38: =Planificación!I38 -> 5 | F38: Analista QA + Analista Funcional / de Negocio | G38: =WORKDAY(H37,1,Feriados) -> 46449 | H38: =IF(E38=0,G38,WORKDAY(G38,E38-1,Feriados)) -> 46455 | I38: No | J38: 0% | K38: 4 h/día por disponibilidad de usuarios de obra | L38: 13 | M38: No | N38: 1.8.2 | O38: 1.8
A39: H05 | B39: Hito: Release 1 aceptada | C39: A30 | D39: FS | E39: =Planificación!I39 -> 0 | F39: Hito | G39: =MAX(H38) -> 46455 | H39: =IF(E39=0,G39,WORKDAY(G39,E39-1,Feriados)) -> 46455 | I39: Sí | J39: 0% | L39: 13 | M39: No | N39: 1.8.2 | O39: 1.8
A40: A31 | B40: Ejecutar pruebas de sistema de Release 2 (con regresión) y corregir defectos | C40: A23, A24, A26, H05 | D40: FS | E40: =Planificación!I40 -> 10 | F40: Analista QA + Desarrollador Backend + Desarrollador Frontend/Móvil | G40: =WORKDAY(MAX(H31,H32,H34,H39),1,Feriados) -> 46476 | H40: =IF(E40=0,G40,WORKDAY(G40,E40-1,Feriados)) -> 46489 | I40: No | J40: 0% | K40: 2 QA + las 2 células de desarrollo | L40: 0 | M40: Sí | N40: 1.8.3 | O40: 1.8
A41: A32 | B41: Ejecutar la prueba de seguridad externa y corregir hallazgos | C41: A31 | D41: FS | E41: =Planificación!I41 -> 8 | F41: Ingeniero DevOps / Cloud | G41: =WORKDAY(H40,1,Feriados) -> 46490 | H41: =IF(E41=0,G41,WORKDAY(G41,E41-1,Feriados)) -> 46499 | I41: No | J41: 0% | K41: Servicio externo; duración fijada por el proveedor | L41: 0 | M41: Sí | N41: 1.8.3 | O41: 1.8
...

Sheet Carta Gantt
A1: 6. Carta Gantt — Vista temporal del cronograma (diaria) — Horizonte Conecta
C2: Fecha límite: | D2: =Calendario!$B$7 -> 46603 | E2: Inicio vista: | F2: =IFERROR(MIN(Cronograma!G4:G55),TODAY()) -> 46300 | G2: =IF(DAY(G3)=1,G3,"") | H2: =IF(DAY(H3)=1,H3,"") | I2: =IF(DAY(I3)=1,I3,"") | J2: =IF(DAY(J3)=1,J3,"") | K2: =IF(DAY(K3)=1,K3,"") | L2: =IF(DAY(L3)=1,L3,"") | M2: =IF(DAY(M3)=1,M3,"") | N2: =IF(DAY(N3)=1,N3,"") | ... KZ2: =IF(DAY(KZ3)=1,KZ3,"")
A3: ID | B3: Actividad | C3: Inicio | D3: Fin | E3: Tipo | F3: =$F$2+0 -> 46300 | G3: =$F$2+1 -> 46301 | H3: =$F$2+2 -> 46302 | I3: =$F$2+3 -> 46303 | J3: =$F$2+4 -> 46304 | K3: =$F$2+5 -> 46305 | L3: =$F$2+6 -> 46306 | M3: =$F$2+7 -> 46307 | N3: =$F$2+8 -> 46308 | O3: =$F$2+9 -> 46309 | P3: =$F$2+10 -> 46310 | Q3: =$F$2+11 -> 46311 | R3: =$F$2+12 -> 46312 | S3: =$F$2+13 -> 46313 | T3: =$F$2+14 -> 46314 | U3: =$F$2+15 -> 46315 | V3: =$F$2+16 -> 46316 | W3: =$F$2+17 -> 46317 | X3: =$F$2+18 -> 46318 | Y3: =$F$2+19 -> 46319 | Z3: =$F$2+20 -> 46320 | AA3: =$F$2+21 -> 46321 | AB3: =$F$2+22 -> 46322 | AC3: =$F$2+23 -> 46323 | AD3: =$F$2+24 -> 46324 | AE3: =$F$2+25 -> 46325 | AF3: =$F$2+26 -> 46326 | AG3: =$F$2+27 -> 46327 | AH3: =$F$2+28 -> 46328 | AI3: =$F$2+29 -> 46329 | AJ3: =$F$2+30 -> 46330 | AK3: =$F$2+31 -> 46331 | AL3: =$F$2+32 -> 46332 | AM3: =$F$2+33 -> 46333 | AN3: =$F$2+34 -> 46334 | AO3: =$F$2+35 -> 46335 | AP3: =$F$2+36 -> 46336 | AQ3: =$F$2+37 -> 46337 | AR3: =$F$2+38 -> 46338 | AS3: =$F$2+39 -> 46339 | AT3: =$F$2+40 -> 46340 | AU3: =$F$2+41 -> 46341 | AV3: =$F$2+42 -> 46342 | AW3: =$F$2+43 -> 46343 | AX3: =$F$2+44 -> 46344 | AY3: =$F$2+45 -> 46345 | AZ3: =$F$2+46 -> 46346 | BA3: =$F$2+47 -> 46347 | BB3: =$F$2+48 -> 46348 | BC3: =$F$2+49 -> 46349 | BD3: =$F$2+50 -> 46350 | BE3: =$F$2+51 -> 46351 | BF3: =$F$2+52 -> 46352 | BG3: =$F$2+53 -> 46353 | BH3: =$F$2+54 -> 46354 | BI3: =$F$2+55 -> 46355 | BJ3: =$F$2+56 -> 46356 | BK3: =$F$2+57 -> 46357 | BL3: =$F$2+58 -> 46358 | BM3: =$F$2+59 -> 46359 | BN3: =$F$2+60 -> 46360 | BO3: =$F$2+61 -> 46361 | BP3: =$F$2+62 -> 46362 | BQ3: =$F$2+63 -> 46363 | BR3: =$F$2+64 -> 46364 | BS3: =$F$2+65 -> 46365 | BT3: =$F$2+66 -> 46366 | BU3: =$F$2+67 -> 46367 | BV3: =$F$2+68 -> 46368 | BW3: =$F$2+69 -> 46369 | BX3: =$F$2+70 -> 46370 | BY3: =$F$2+71 -> 46371 | BZ3: =$F$2+72 -> 46372 | CA3: =$F$2+73 -> 46373 | CB3: =$F$2+74 -> 46374 | CC3: =$F$2+75 -> 46375 | CD3: =$F$2+76 -> 46376 | CE3: =$F$2+77 -> 46377 | CF3: =$F$2+78 -> 46378 | CG3: =$F$2+79 -> 46379 | CH3: =$F$2+80 -> 46380 | CI3: =$F$2+81 -> 46381 | CJ3: =$F$2+82 -> 46382 | CK3: =$F$2+83 -> 46383 | CL3: =$F$2+84 -> 46384 | CM3: =$F$2+85 -> 46385 | CN3: =$F$2+86 -> 46386 | CO3: =$F$2+87 -> 46387 | CP3: =$F$2+88 -> 46388 | CQ3: =$F$2+89 -> 46389 | CR3: =$F$2+90 -> 46390 | CS3: =$F$2+91 -> 46391 | CT3: =$F$2+92 -> 46392 | CU3: =$F$2+93 -> 46393 | CV3: =$F$2+94 -> 46394 | CW3: =$F$2+95 -> 46395 | CX3: =$F$2+96 -> 46396 | CY3: =$F$2+97 -> 46397 | CZ3: =$F$2+98 -> 46398 | DA3: =$F$2+99 -> 46399 | DB3: =$F$2+100 -> 46400 | DC3: =$F$2+101 -> 46401 | DD3: =$F$2+102 -> 46402 | DE3: =$F$2+103 -> 46403 | DF3: =$F$2+104 -> 46404 | DG3: =$F$2+105 -> 46405 | DH3: =$F$2+106 -> 46406 | DI3: =$F$2+107 -> 46407 | DJ3: =$F$2+108 -> 46408 | DK3: =$F$2+109 -> 46409 | DL3: =$F$2+110 -> 46410 | DM3: =$F$2+111 -> 46411 | DN3: =$F$2+112 -> 46412 | DO3: =$F$2+113 -> 46413 | DP3: =$F$2+114 -> 46414 | DQ3: =$F$2+115 -> 46415 | DR3: =$F$2+116 -> 46416 | DS3: =$F$2+117 -> 46417 | DT3: =$F$2+118 -> 46418 | DU3: =$F$2+119 -> 46419 | DV3: =$F$2+120 -> 46420 | DW3: =$F$2+121 -> 46421 | DX3: =$F$2+122 -> 46422 | DY3: =$F$2+123 -> 46423 | DZ3: =$F$2+124 -> 46424 | EA3: =$F$2+125 -> 46425 | EB3: =$F$2+126 -> 46426 | EC3: =$F$2+127 -> 46427 | ED3: =$F$2+128 -> 46428 | EE3: =$F$2+129 -> 46429 | EF3: =$F$2+130 -> 46430 | EG3: =$F$2+131 -> 46431 | EH3: =$F$2+132 -> 46432 | EI3: =$F$2+133 -> 46433 | EJ3: =$F$2+134 -> 46434 | EK3: =$F$2+135 -> 46435 | EL3: =$F$2+136 -> 46436 | EM3: =$F$2+137 -> 46437 | EN3: =$F$2+138 -> 46438 | EO3: =$F$2+139 -> 46439 | EP3: =$F$2+140 -> 46440 | EQ3: =$F$2+141 -> 46441 | ER3: =$F$2+142 -> 46442 | ES3: =$F$2+143 -> 46443 | ET3: =$F$2+144 -> 46444 | EU3: =$F$2+145 -> 46445 | EV3: =$F$2+146 -> 46446 | EW3: =$F$2+147 -> 46447 | EX3: =$F$2+148 -> 46448 | EY3: =$F$2+149 -> 46449 | EZ3: =$F$2+150 -> 46450 | FA3: =$F$2+151 -> 46451 | FB3: =$F$2+152 -> 46452 | FC3: =$F$2+153 -> 46453 | FD3: =$F$2+154 -> 46454 | FE3: =$F$2+155 -> 46455 | FF3: =$F$2+156 -> 46456 | FG3: =$F$2+157 -> 46457 | FH3: =$F$2+158 -> 46458 | FI3: =$F$2+159 -> 46459 | FJ3: =$F$2+160 -> 46460 | FK3: =$F$2+161 -> 46461 | FL3: =$F$2+162 -> 46462 | FM3: =$F$2+163 -> 46463 | FN3: =$F$2+164 -> 46464 | FO3: =$F$2+165 -> 46465 | FP3: =$F$2+166 -> 46466 | FQ3: =$F$2+167 -> 46467 | FR3: =$F$2+168 -> 46468 | FS3: =$F$2+169 -> 46469 | FT3: =$F$2+170 -> 46470 | FU3: =$F$2+171 -> 46471 | FV3: =$F$2+172 -> 46472 | FW3: =$F$2+173 -> 46473 | FX3: =$F$2+174 -> 46474 | FY3: =$F$2+175 -> 46475 | FZ3: =$F$2+176 -> 46476 | GA3: =$F$2+177 -> 46477 | GB3: =$F$2+178 -> 46478 | GC3: =$F$2+179 -> 46479 | GD3: =$F$2+180 -> 46480 | GE3: =$F$2+181 -> 46481 | GF3: =$F$2+182 -> 46482 | GG3: =$F$2+183 -> 46483 | GH3: =$F$2+184 -> 46484 | GI3: =$F$2+185 -> 46485 | GJ3: =$F$2+186 -> 46486 | GK3: =$F$2+187 -> 46487 | GL3: =$F$2+188 -> 46488 | GM3: =$F$2+189 -> 46489 | GN3: =$F$2+190 -> 46490 | GO3: =$F$2+191 -> 46491 | GP3: =$F$2+192 -> 46492 | GQ3: =$F$2+193 -> 46493 | GR3: =$F$2+194 -> 46494 | GS3: =$F$2+195 -> 46495 | GT3: =$F$2+196 -> 46496 | GU3: =$F$2+197 -> 46497 | GV3: =$F$2+198 -> 46498 | GW3: =$F$2+199 -> 46499 | GX3: =$F$2+200 -> 46500 | GY3: =$F$2+201 -> 46501 | GZ3: =$F$2+202 -> 46502 | HA3: =$F$2+203 -> 46503 | HB3: =$F$2+204 -> 46504 | HC3: =$F$2+205 -> 46505 | HD3: =$F$2+206 -> 46506 | HE3: =$F$2+207 -> 46507 | HF3: =$F$2+208 -> 46508 | HG3: =$F$2+209 -> 46509 | HH3: =$F$2+210 -> 46510 | HI3: =$F$2+211 -> 46511 | HJ3: =$F$2+212 -> 46512 | HK3: =$F$2+213 -> 46513 | HL3: =$F$2+214 -> 46514 | HM3: =$F$2+215 -> 46515 | HN3: =$F$2+216 -> 46516 | HO3: =$F$2+217 -> 46517 | HP3: =$F$2+218 -> 46518 | HQ3: =$F$2+219 -> 46519 | HR3: =$F$2+220 -> 46520 | HS3: =$F$2+221 -> 46521 | HT3: =$F$2+222 -> 46522 | HU3: =$F$2+223 -> 46523 | HV3: =$F$2+224 -> 46524 | HW3: =$F$2+225 -> 46525 | HX3: =$F$2+226 -> 46526 | HY3: =$F$2+227 -> 46527 | HZ3: =$F$2+228 -> 46528 | IA3: =$F$2+229 -> 46529 | IB3: =$F$2+230 -> 46530 | IC3: =$F$2+231 -> 46531 | ID3: =$F$2+232 -> 46532 | IE3: =$F$2+233 -> 46533 | IF3: =$F$2+234 -> 46534 | IG3: =$F$2+235 -> 46535 | IH3: =$F$2+236 -> 46536 | II3: =$F$2+237 -> 46537 | IJ3: =$F$2+238 -> 46538 | IK3: =$F$2+239 -> 46539 | IL3: =$F$2+240 -> 46540 | IM3: =$F$2+241 -> 46541 | IN3: =$F$2+242 -> 46542 | IO3: =$F$2+243 -> 46543 | IP3: =$F$2+244 -> 46544 | IQ3: =$F$2+245 -> 46545 | IR3: =$F$2+246 -> 46546 | IS3: =$F$2+247 -> 46547 | IT3: =$F$2+248 -> 46548 | IU3: =$F$2+249 -> 46549 | IV3: =$F$2+250 -> 46550 | IW3: =$F$2+251 -> 46551 | IX3: =$F$2+252 -> 46552 | IY3: =$F$2+253 -> 46553 | IZ3: =$F$2+254 -> 46554 | JA3: =$F$2+255 -> 46555 | JB3: =$F$2+256 -> 46556 | JC3: =$F$2+257 -> 46557 | JD3: =$F$2+258 -> 46558 | JE3: =$F$2+259 -> 46559 | JF3: =$F$2+260 -> 46560 | JG3: =$F$2+261 -> 46561 | JH3: =$F$2+262 -> 46562 | JI3: =$F$2+263 -> 46563 | JJ3: =$F$2+264 -> 46564 | JK3: =$F$2+265 -> 46565 | JL3: =$F$2+266 -> 46566 | JM3: =$F$2+267 -> 46567 | JN3: =$F$2+268 -> 46568 | JO3: =$F$2+269 -> 46569 | JP3: =$F$2+270 -> 46570 | JQ3: =$F$2+271 -> 46571 | JR3: =$F$2+272 -> 46572 | JS3: =$F$2+273 -> 46573 | JT3: =$F$2+274 -> 46574 | JU3: =$F$2+275 -> 46575 | JV3: =$F$2+276 -> 46576 | JW3: =$F$2+277 -> 46577 | JX3: =$F$2+278 -> 46578 | JY3: =$F$2+279 -> 46579 | JZ3: =$F$2+280 -> 46580 | KA3: =$F$2+281 -> 46581 | KB3: =$F$2+282 -> 46582 | KC3: =$F$2+283 -> 46583 | KD3: =$F$2+284 -> 46584 | KE3: =$F$2+285 -> 46585 | KF3: =$F$2+286 -> 46586 | KG3: =$F$2+287 -> 46587 | KH3: =$F$2+288 -> 46588 | KI3: =$F$2+289 -> 46589 | KJ3: =$F$2+290 -> 46590 | KK3: =$F$2+291 -> 46591 | KL3: =$F$2+292 -> 46592 | KM3: =$F$2+293 -> 46593 | KN3: =$F$2+294 -> 46594 | KO3: =$F$2+295 -> 46595 | KP3: =$F$2+296 -> 46596 | KQ3: =$F$2+297 -> 46597 | KR3: =$F$2+298 -> 46598 | KS3: =$F$2+299 -> 46599 | KT3: =$F$2+300 -> 46600 | KU3: =$F$2+301 -> 46601 | KV3: =$F$2+302 -> 46602 | KW3: =$F$2+303 -> 46603 | KX3: =$F$2+304 -> 46604 | KY3: =$F$2+305 -> 46605 | KZ3: =$F$2+306 -> 46606
A4: =Cronograma!A4 -> A01 | B4: =Cronograma!B4 -> Constituir equipo y comité directivo, y realizar kick-off | C4: =Cronograma!G4 -> 46300 | D4: =Cronograma!H4 -> 46303 | E4: =IF(Cronograma!I4="Sí","◆",IF(Cronograma!M4="Sí","RC","")) -> RC
A5: =Cronograma!A5 -> H01 | B5: =Cronograma!B5 -> Hito: Kick-off realizado | C5: =Cronograma!G5 -> 46303 | D5: =Cronograma!H5 -> 46303 | E5: =IF(Cronograma!I5="Sí","◆",IF(Cronograma!M5="Sí","RC","")) -> ◆
A6: =Cronograma!A6 -> A02 | B6: =Cronograma!B6 -> Elaborar y aprobar plan de dirección del proyecto | C6: =Cronograma!G6 -> 46304 | D6: =Cronograma!H6 -> 46318 | E6: =IF(Cronograma!I6="Sí","◆",IF(Cronograma!M6="Sí","RC",""))
A7: =Cronograma!A7 -> A03 | B7: =Cronograma!B7 -> Realizar seguimiento y control (comités quincenales, riesgos y cambios) | C7: =Cronograma!G7 -> 46321 | D7: =Cronograma!H7 -> 46560 | E7: =IF(Cronograma!I7="Sí","◆",IF(Cronograma!M7="Sí","RC",""))
A8: =Cronograma!A8 -> A04 | B8: =Cronograma!B8 -> Elaborar informe final, lecciones aprendidas y acta de cierre | C8: =Cronograma!G8 -> 46575 | D8: =Cronograma!H8 -> 46580 | E8: =IF(Cronograma!I8="Sí","◆",IF(Cronograma!M8="Sí","RC","")) -> RC
A9: =Cronograma!A9 -> H10 | B9: =Cronograma!B9 -> Hito: Cierre formal del proyecto | C9: =Cronograma!G9 -> 46580 | D9: =Cronograma!H9 -> 46580 | E9: =IF(Cronograma!I9="Sí","◆",IF(Cronograma!M9="Sí","RC","")) -> ◆
A10: =Cronograma!A10 -> A05 | B10: =Cronograma!B10 -> Levantar procesos en las 3 obras piloto y en oficina central | C10: =Cronograma!G10 -> 46304 | D10: =Cronograma!H10 -> 46314 | E10: =IF(Cronograma!I10="Sí","◆",IF(Cronograma!M10="Sí","RC","")) -> RC
A11: =Cronograma!A11 -> A06 | B11: =Cronograma!B11 -> Documentar diagnóstico y línea base de indicadores | C11: =Cronograma!G11 -> 46315 | D11: =Cronograma!H11 -> 46318 | E11: =IF(Cronograma!I11="Sí","◆",IF(Cronograma!M11="Sí","RC","")) -> RC
A12: =Cronograma!A12 -> A07 | B12: =Cronograma!B12 -> Especificar requisitos e historias de usuario (incluye offline y seguridad) | C12: =Cronograma!G12 -> 46321 | D12: =Cronograma!H12 -> 46335 | E12: =IF(Cronograma!I12="Sí","◆",IF(Cronograma!M12="Sí","RC",""))
A13: =Cronograma!A13 -> A08 | B13: =Cronograma!B13 -> Definir indicadores de las 6 preguntas de la gerencia y validarlos con Finanzas | C13: =Cronograma!G13 -> 46321 | D13: =Cronograma!H13 -> 46329 | E13: =IF(Cronograma!I13="Sí","◆",IF(Cronograma!M13="Sí","RC",""))
A14: =Cronograma!A14 -> A09 | B14: =Cronograma!B14 -> Priorizar backlog en Release 1 y 2 y aprobar el alcance en comité | C14: =Cronograma!G14 -> 46336 | D14: =Cronograma!H14 -> 46337 | E14: =IF(Cronograma!I14="Sí","◆",IF(Cronograma!M14="Sí","RC",""))
A15: =Cronograma!A15 -> H02 | B15: =Cronograma!B15 -> Hito: Alcance aprobado | C15: =Cronograma!G15 -> 46337 | D15: =Cronograma!H15 -> 46337 | E15: =IF(Cronograma!I15="Sí","◆",IF(Cronograma!M15="Sí","RC","")) -> ◆
... A55: =Cronograma!A55 -> A42 | B55: =Cronograma!B55 -> Elaborar documentación y manuales, y traspasar la operación a TI | C55: =Cronograma!G55 -> 46503 | D55: =Cronograma!H55 -> 46518 | E55: =IF(Cronograma!I55="Sí","◆",IF(Cronograma!M55="Sí","RC",""))
B57: Leyenda: rojo = actividad en ruta crítica · azul = actividad con holgura · naranjo = hito · gris = fin de semana · columna rosada = fecha límite (04-08-2027)

Sheet Gantt resumen
A1: 7. Carta Gantt resumen (semanal) por entregable de la EDT e hitos — Horizonte Conecta
C2: Fecha límite: | D2: =Calendario!$B$7 -> 46603 | E2: S1 | F2: S2 | G2: S3 | H2: S4 | I2: S5 | J2: S6 | K2: S7 | L2: S8 | M2: S9 | N2: S10 | O2: S11 | P2: S12 | Q2: S13 | R2: S14 | S2: S15 | T2: S16 | U2: S17 | V2: S18 | W2: S19 | X2: S20 | Y2: S21 | Z2: S22 | AA2: S23 | AB2: S24 | AC2: S25 | AD2: S26 | AE2: S27 | AF2: S28 | AG2: S29 | AH2: S30 | AI2: S31 | AJ2: S32 | AK2: S33 | AL2: S34 | AM2: S35 | AN2: S36 | AO2: S37 | AP2: S38 | AQ2: S39 | AR2: S40 | AS2: S41 | AT2: S42 | AU2: S43 | AV2: S44 | AW2: S45
A3: EDT | B3: Entregable / hito | C3: Inicio | D3: Fin | E3: 46300 | F3: 46307 | G3: 46314 | H3: 46321 | I3: 46328 | J3: 46335 | K3: 46342 | L3: 46349 | M3: 46356 | N3: 46363 | O3: 46370 | P3: 46377 | Q3: 46384 | R3: 46391 | S3: 46398 | T3: 46405 | U3: 46412 | V3: 46419 | W3: 46426 | X3: 46433 | Y3: 46440 | Z3: 46447 | AA3: 46454 | AB3: 46461 | AC3: 46468 | AD3: 46475 | AE3: 46482 | AF3: 46489 | AG3: 46496 | AH3: 46503 | AI3: 46510 | AJ3: 46517 | AK3: 46524 | AL3: 46531 | AM3: 46538 | AN3: 46545 | AO3: 46552 | AP3: 46559 | AQ3: 46566 | AR3: 46573 | AS3: 46580 | AT3: 46587 | AU3: 46594 | AV3: 46601 | AW3: 46608
A4: 1.0 | B4: Horizonte Conecta – Plataforma de gestión operacional de obras | C4: =MIN(Cronograma!$G$4:$G$55) -> 46300 | D4: =MAX(Cronograma!$H$4:$H$55) -> 46580
A5: 1.1 | B5: Gestión del proyecto | C5: =_xlfn.MINIFS(Cronograma!$G$4:$G$55,Cronograma!$O$4:$O$55,A5) -> 46300 | D5: =_xlfn.MAXIFS(Cronograma!$H$4:$H$55,Cronograma!$O$4:$O$55,A5) -> 46580
A6: 1.2 | B6: Diagnóstico y requisitos | C6: =_xlfn.MINIFS(Cronograma!$G$4:$G$55,Cronograma!$O$4:$O$55,A6) -> 46304 | D6: =_xlfn.MAXIFS(Cronograma!$H$4:$H$55,Cronograma!$O$4:$O$55,A6) -> 46337
A7: 1.3 | B7: Diseño de la solución | C7: =_xlfn.MINIFS(Cronograma!$G$4:$G$55,Cronograma!$O$4:$O$55,A7) -> 46304 | D7: =_xlfn.MAXIFS(Cronograma!$H$4:$H$55,Cronograma!$O$4:$O$55,A7) -> 46365
A8: 1.4 | B8: Plataforma base | C8: =_xlfn.MINIFS(Cronograma!$G$4:$G$55,Cronograma!$O$4:$O$55,A8) -> 46346 | D8: =_xlfn.MAXIFS(Cronograma!$H$4:$H$55,Cronograma!$O$4:$O$55,A8) -> 46395
A9: 1.5 | B9: Integraciones corporativas | C9: =_xlfn.MINIFS(Cronograma!$G$4:$G$55,Cronograma!$O$4:$O$55,A9) -> 46370 | D9: =_xlfn.MAXIFS(Cronograma!$H$4:$H$55,Cronograma!$O$4:$O$55,A9) -> 46450
A10: 1.6 | B10: Release 1: operación de obra | C10: =_xlfn.MINIFS(Cronograma!$G$4:$G$55,Cronograma!$O$4:$O$55,A10) -> 46398 | D10: =_xlfn.MAXIFS(Cronograma!$H$4:$H$55,Cronograma!$O$4:$O$55,A10) -> 46434
A11: 1.7 | B11: Release 2: control económico | C11: =_xlfn.MINIFS(Cronograma!$G$4:$G$55,Cronograma!$O$4:$O$55,A11) -> 46398 | D11: =_xlfn.MAXIFS(Cronograma!$H$4:$H$55,Cronograma!$O$4:$O$55,A11) -> 46475
A12: 1.8 | B12: Pruebas y calidad | C12: =_xlfn.MINIFS(Cronograma!$G$4:$G$55,Cronograma!$O$4:$O$55,A12) -> 46338 | D12: =_xlfn.MAXIFS(Cronograma!$H$4:$H$55,Cronograma!$O$4:$O$55,A12) -> 46499
A13: 1.9 | B13: Piloto y gestión del cambio | C13: =_xlfn.MINIFS(Cronograma!$G$4:$G$55,Cronograma!$O$4:$O$55,A13) -> 46398 | D13: =_xlfn.MAXIFS(Cronograma!$H$4:$H$55,Cronograma!$O$4:$O$55,A13) -> 46574
A14: 1.10 | B14: Transición a operación | C14: =_xlfn.MINIFS(Cronograma!$G$4:$G$55,Cronograma!$O$4:$O$55,A14) -> 46503 | D14: =_xlfn.MAXIFS(Cronograma!$H$4:$H$55,Cronograma!$O$4:$O$55,A14) -> 46518
A15: H01 | B15: ◆ Kick-off realizado | C15: =Cronograma!H5 -> 46303 | D15: =Cronograma!H5 -> 46303
A16: H02 | B16: ◆ Alcance aprobado | C16: =Cronograma!H15 -> 46337 | D16: =Cronograma!H15 -> 46337
A17: H03 | B17: ◆ Diseño de solución aprobado | C17: =Cronograma!H19 -> 46365 | D17: =Cronograma!H19 -> 46365
A18: H04 | B18: ◆ Plataforma base operativa | C18: =Cronograma!H23 -> 46395 | D18: =Cronograma!H23 -> 46395
A19: H05 | B19: ◆ Release 1 aceptada | C19: =Cronograma!H39 -> 46455 | D19: =Cronograma!H39 -> 46455
A20: H06 | B20: ◆ Release 1 en operación en las 3 obras | C20: =Cronograma!H47 -> 46461 | D20: =Cronograma!H47 -> 46461
A21: H07 | B21: ◆ Release 2 aceptada | C21: =Cronograma!H43 -> 46499 | D21: =Cronograma!H43 -> 46499
A22: H08 | B22: ◆ Release 2 en operación en las 3 obras | C22: =Cronograma!H51 -> 46500 | D22: =Cronograma!H51 -> 46500
A23: H09 | B23: ◆ Evaluación del piloto aprobada | C23: =Cronograma!H54 -> 46574 | D23: =Cronograma!H54 -> 46574
A24: H10 | B24: ◆ Cierre formal del proyecto | C24: =Cronograma!H9 -> 46580 | D24: =Cronograma!H9 -> 46580
B26: Barras azules = período del entregable (nivel 2 EDT) calculado desde el Cronograma · naranjo = semana del hito · rosado = semana de la fecha límite
